<?xml version="1.0" ?>
<robot name="New_bot" xmlns:xacro="http://www.ros.org/wiki/xacro">

<xacro:include filename="$(find New_bot_description)/urdf/materials.xacro" />
<xacro:include filename="$(find New_bot_description)/urdf/New_bot.trans" />
<xacro:include filename="$(find New_bot_description)/urdf/New_bot.gazebo" />
<link name="base_link">
  <inertial>
    <origin rpy="0 0 0" xyz="-0.010212346248804129 6.7302717670420285e-18 0.04397952899209392"/>
    <mass value="1.8243213497054398"/>
    <inertia ixx="0.001922" ixy="-0.0" ixz="0.000367" iyy="0.003508" iyz="0.0" izz="0.004481"/>
  </inertial>
  <visual>
    <origin rpy="0 0 0" xyz="0 0 0"/>
    <geometry>
      <mesh filename="package://New_bot_description/meshes/base_link.stl" scale="0.001 0.001 0.001"/>
    </geometry>
    <material name="silver"/>
  </visual>
  <collision>
    <origin rpy="0 0 0" xyz="0 0 0"/>
    <geometry>
      <mesh filename="package://New_bot_description/meshes/base_link.stl" scale="0.001 0.001 0.001"/>
    </geometry>
  </collision>
</link>

<link name="r_wheel_1">
  <inertial>
    <origin rpy="0 0 0" xyz="-9.089827363029102e-10 -0.012500000000000004 2.0861626315316073e-10"/>
    <mass value="0.12323427319098348"/>
    <inertia ixx="4.2e-05" ixy="0.0" ixz="-0.0" iyy="7.1e-05" iyz="-0.0" izz="4.2e-05"/>
  </inertial>
  <visual>
    <origin rpy="0 0 0" xyz="0.061 0.057 -0.0335"/>
    <geometry>
      <mesh filename="package://New_bot_description/meshes/r_wheel_1.stl" scale="0.001 0.001 0.001"/>
    </geometry>
    <material name="silver"/>
  </visual>
  <collision>
    <origin rpy="0 0 0" xyz="0.061 0.057 -0.0335"/>
    <geometry>
      <mesh filename="package://New_bot_description/meshes/r_wheel_1.stl" scale="0.001 0.001 0.001"/>
    </geometry>
  </collision>
</link>

<link name="l_wheel_1">
  <inertial>
    <origin rpy="0 0 0" xyz="-9.089827363029102e-10 0.012500000000000004 2.0861626315316073e-10"/>
    <mass value="0.12323427319098348"/>
    <inertia ixx="4.2e-05" ixy="0.0" ixz="-0.0" iyy="7.1e-05" iyz="0.0" izz="4.2e-05"/>
  </inertial>
  <visual>
    <origin rpy="0 0 0" xyz="0.061 -0.057 -0.0335"/>
    <geometry>
      <mesh filename="package://New_bot_description/meshes/l_wheel_1.stl" scale="0.001 0.001 0.001"/>
    </geometry>
    <material name="silver"/>
  </visual>
  <collision>
    <origin rpy="0 0 0" xyz="0.061 -0.057 -0.0335"/>
    <geometry>
      <mesh filename="package://New_bot_description/meshes/l_wheel_1.stl" scale="0.001 0.001 0.001"/>
    </geometry>
  </collision>
</link>

<link name="lidar_1">
  <inertial>
    <origin rpy="0 0 0" xyz="0.0 -7.237528875152536e-18 0.0049999999999999906"/>
    <mass value="0.1541343895667492"/>
    <inertia ixx="2.5e-05" ixy="-0.0" ixz="0.0" iyy="2.5e-05" iyz="0.0" izz="4.8e-05"/>
  </inertial>
  <visual>
    <origin rpy="0 0 0" xyz="0.04 -0.0 -0.0895"/>
    <geometry>
      <mesh filename="package://New_bot_description/meshes/lidar_1.stl" scale="0.001 0.001 0.001"/>
    </geometry>
    <material name="silver"/>
  </visual>
  <collision>
    <origin rpy="0 0 0" xyz="0.04 -0.0 -0.0895"/>
    <geometry>
      <mesh filename="package://New_bot_description/meshes/lidar_1.stl" scale="0.001 0.001 0.001"/>
    </geometry>
  </collision>
</link>

<link name="caster_1">
  <inertial>
    <origin rpy="0 0 0" xyz="-0.029999999999999985 0.0 -0.008390257768896393"/>
    <mass value="0.01338926411876868"/>
    <inertia ixx="1e-06" ixy="-0.0" ixz="0.0" iyy="1e-06" iyz="0.0" izz="1e-06"/>
  </inertial>
  <visual>
    <origin rpy="0 0 0" xyz="-0.075 -0.0 -0.0195"/>
    <geometry>
      <mesh filename="package://New_bot_description/meshes/caster_1.stl" scale="0.001 0.001 0.001"/>
    </geometry>
    <material name="silver"/>
  </visual>
  <collision>
    <origin rpy="0 0 0" xyz="-0.075 -0.0 -0.0195"/>
    <geometry>
      <mesh filename="package://New_bot_description/meshes/caster_1.stl" scale="0.001 0.001 0.001"/>
    </geometry>
  </collision>
</link>

<link name="rpi_1">
  <inertial>
    <origin rpy="0 0 0" xyz="-0.024145426051437997 0.016029779281400276 0.004888830680916917"/>
    <mass value="0.13472167579144476"/>
    <inertia ixx="8.3e-05" ixy="0.0" ixz="-0.0" iyy="4.1e-05" iyz="-9e-06" izz="0.000118"/>
  </inertial>
  <visual>
    <origin rpy="0 0 0" xyz="-0.071 -0.0 -0.0495"/>
    <geometry>
      <mesh filename="package://New_bot_description/meshes/rpi_1.stl" scale="0.001 0.001 0.001"/>
    </geometry>
    <material name="silver"/>
  </visual>
  <collision>
    <origin rpy="0 0 0" xyz="-0.071 -0.0 -0.0495"/>
    <geometry>
      <mesh filename="package://New_bot_description/meshes/rpi_1.stl" scale="0.001 0.001 0.001"/>
    </geometry>
  </collision>
</link>

<joint name="Rev1" type="continuous">
  <origin rpy="0 0 0" xyz="-0.061 -0.057 0.0335"/>
  <parent link="base_link"/>
  <child link="r_wheel_1"/>
  <axis xyz="0.0 1.0 0.0"/>
</joint>

<joint name="Rev2" type="continuous">
  <origin rpy="0 0 0" xyz="-0.061 0.057 0.0335"/>
  <parent link="base_link"/>
  <child link="l_wheel_1"/>
  <axis xyz="0.0 1.0 0.0"/>
</joint>

<joint name="Rigid3" type="fixed">
  <origin rpy="0 0 0" xyz="-0.04 0.0 0.0895"/>
  <parent link="base_link"/>
  <child link="lidar_1"/>
</joint>

<joint name="Rigid4" type="fixed">
  <origin rpy="0 0 0" xyz="0.075 0.0 0.0195"/>
  <parent link="base_link"/>
  <child link="caster_1"/>
</joint>

<joint name="Rigid5" type="fixed">
  <origin rpy="0 0 0" xyz="0.071 0.0 0.0495"/>
  <parent link="base_link"/>
  <child link="rpi_1"/>
</joint>

</robot>
